Workbook

Sheet Sheet1
A1: 线上订单号 | B1: 品牌 | C1: 店铺 | D1: 订单日期 | E1: 商品名称 | F1: 工厂 | G1: 商品工厂 | H1: 商品编码 | I1: 成本价 | J1: 标费运费 | K1: 平台扣点 | L1: 总成本 | M1: 销售数量 | N1: 销售金额 | O1: 销售毛利 | P1: 销售毛利率
A2: 5122610136099021717 | B2: 初医生 | C2: 淘宝天猫-初医生旗舰店 | D2: 46205 | E2: 长颈鹿抱枕内衬款 | F2: 佳雷 | G2: 佳雷-长颈鹿抱枕内衬款 | H2: CYS-JLBZCJLPWC01001 | I2: =VLOOKUP(H2,[1]物料!$A$1:$M$65536,13,0) -> 43.30 | J2: 3.5 | K2: =N2*0.05 -> 4.896 | L2: =I2+J2+K2 -> 51.696 | M2: 1 | N2: 97.92 | O2: =N2-L2 -> 46.224 | P2: =O2/N2 -> 0.47205882
A3: 5122574748819055816 | B3: 猫人 | C3: 淘宝天猫-猫人严选旗舰店 | D3: 46205 | E3: 冥想坐垫 | F3: 佳雷 | G3: 佳雷-冥想坐垫 | H3: JLZDMXKJC01001 | I3: =VLOOKUP(H3,[1]物料!$A$1:$M$65536,13,0) -> 115.60 | J3: 13.5 | K3: =N3*0.05 -> 12.139 | L3: =I3+J3+K3 -> 141.239 | M3: 1 | N3: 242.78 | O3: =N3-L3 -> 101.541 | P3: =O3/N3 -> 0.41824285
A4: 5122574748819055816 | B4: 猫人 | C4: 淘宝天猫-猫人严选旗舰店 | D4: 46205 | E4: 冥想坐垫 | F4: 佳雷 | G4: 佳雷-冥想坐垫 | H4: JLZDMXKJC01002 | I4: =VLOOKUP(H4,[1]物料!$A$1:$M$65536,13,0) -> 115.60 | J4: 13.5 | K4: =N4*0.05 -> 12.139 | L4: =I4+J4+K4 -> 141.239 | M4: 1 | N4: 242.78 | O4: =N4-L4 -> 101.541 | P4: =O4/N4 -> 0.41824285
A5: 3311087737167074172 | B5: 初医生 | C5: 淘宝天猫-初医生旗舰店 | D5: 46205 | E5: 小袋鼠儿童抱枕中号 | F5: 华雷 | G5: 华雷-小袋鼠儿童抱枕中号 | H5: CYS-XDSETBZBS02 | I5: =VLOOKUP(H5,[1]物料!$A$1:$M$65536,13,0) -> 43.00 | J5: 13.6 | K5: =N5*0.05 -> 5.9755 | L5: =I5+J5+K5 -> 62.5755 | M5: 1 | N5: 119.51 | O5: =N5-L5 -> 56.9345 | P5: =O5/N5 -> 0.47639946
A6: 3311087737167074172 | B6: 初医生 | C6: 淘宝天猫-初医生旗舰店 | D6: 46205 | E6: 小袋鼠儿童抱枕中号 | F6: 华雷 | G6: 华雷-小袋鼠儿童抱枕中号 | H6: CYS-XDSETBZFS05 | I6: =VLOOKUP(H6,[1]物料!$A$1:$M$65536,13,0) -> 43.00 | J6: 13.6 | K6: =N6*0.05 -> 5.9755 | L6: =I6+J6+K6 -> 62.5755 | M6: 1 | N6: 119.51 | O6: =N6-L6 -> 56.9345 | P6: =O6/N6 -> 0.47639946
A7: 5122687897862017910 | B7: 猫人 | C7: 淘宝天猫-猫人严选旗舰店 | D7: 46205 | E7: 冥想坐垫 | F7: 佳雷 | G7: 佳雷-冥想坐垫 | H7: JLZDMXKJC01001 | I7: =VLOOKUP(H7,[1]物料!$A$1:$M$65536,13,0) -> 115.60 | J7: 13.5 | K7: =N7*0.05 -> 12.139 | L7: =I7+J7+K7 -> 141.239 | M7: 1 | N7: 242.78 | O7: =N7-L7 -> 101.541 | P7: =O7/N7 -> 0.41824285
A8: 5122687897862017910 | B8: 猫人 | C8: 淘宝天猫-猫人严选旗舰店 | D8: 46205 | E8: 冥想坐垫 | F8: 佳雷 | G8: 佳雷-冥想坐垫 | H8: JLZDMXKJC01001 | I8: =VLOOKUP(H8,[1]物料!$A$1:$M$65536,13,0) -> 115.60 | J8: 13.5 | K8: =N8*0.05 -> 12.139 | L8: =I8+J8+K8 -> 141.239 | M8: 1 | N8: 242.78 | O8: =N8-L8 -> 101.541 | P8: =O8/N8 -> 0.41824285
A9: 5122687897862017910 | B9: 猫人 | C9: 淘宝天猫-猫人严选旗舰店 | D9: 46205 | E9: 冥想坐垫 | F9: 佳雷 | G9: 佳雷-冥想坐垫 | H9: JLZDMXKJC01001 | I9: =VLOOKUP(H9,[1]物料!$A$1:$M$65536,13,0) -> 115.60 | J9: 13.5 | K9: =N9*0.05 -> 12.139 | L9: =I9+J9+K9 -> 141.239 | M9: 1 | N9: 242.78 | O9: =N9-L9 -> 101.541 | P9: =O9/N9 -> 0.41824285
A10: 5122691605699092108,18266689:5122189155360000907,18266689:5122691605699092108 | B10: 猫人 | C10: 淘宝天猫-猫人严选旗舰店 | D10: 46205 | E10: 芭蕾舞鞋 | F10: 善艺 | G10: 善艺-芭蕾舞鞋 | H10: 芭蕾舞山茶花（白色39-40） | I10: =VLOOKUP(H10,[1]物料!$A$1:$M$65536,13,0) -> 19.00 | J10: 5.4 | K10: =N10*0.05 -> 1.845 | L10: =I10+J10+K10 -> 26.245 | M10: 1 | N10: 36.9 | O10: =N10-L10 -> 10.655 | P10: =O10/N10 -> 0.28875339
A11: 5122691605699092108,18266689:5122189155360000907,18266689:5122691605699092108 | B11: 猫人 | C11: 淘宝天猫-猫人严选旗舰店 | D11: 46205 | E11: 芭蕾舞鞋 | F11: 善艺 | G11: 善艺-芭蕾舞鞋 | H11: 芭蕾舞山茶花（黑色37-38） | I11: =VLOOKUP(H11,[1]物料!$A$1:$M$65536,13,0) -> 19.00 | J11: 5.4 | K11: =N11*0.05 -> 1.845 | L11: =I11+J11+K11 -> 26.245 | M11: 1 | N11: 36.9 | O11: =N11-L11 -> 10.655 | P11: =O11/N11 -> 0.28875339
A12: 260702-641749491250113 | B12: 猫人 | C12: 拼多多-猫人布艺旗舰店 | D12: 46205 | E12: 四叶草褥疮坐垫凝胶卫衣布款 | F12: 佳雷 | G12: 佳雷-四叶草褥疮坐垫凝胶卫衣布款 | H12: JLZDRCNJWYBC01001 | I12: =VLOOKUP(H12,[1]物料!$A$1:$M$65536,13,0) -> 36.10 | J12: 6.5 | K12: =N12*0.05 -> 4.435 | L12: =I12+J12+K12 -> 47.035 | M12: 1 | N12: 88.7 | O12: =N12-L12 -> 41.665 | P12: =O12/N12 -> 0.46972943
A13: 260702-020059287052263 | B13: 初医生 | C13: 拼多多-初医生家纺官方旗舰店 | D13: 46205 | E13: 双层午睡枕 | F13: 佳雷 | G13: 佳雷-双层午睡枕 | H13: CYS-JLWSSCPWP01004 | I13: =VLOOKUP(H13,[1]物料!$A$1:$M$65536,13,0) -> 21.00 | J13: 3 | K13: =N13*0.05 -> 2.495 | L13: =I13+J13+K13 -> 26.495 | M13: 1 | N13: 49.9 | O13: =N13-L13 -> 23.405 | P13: =O13/N13 -> 0.46903808
... A509: 5122183539361098821 | B509: 初医生 | C509: 淘宝天猫-初医生旗舰店 | D509: 46205 | E509: 长颈鹿抱枕内衬款 | F509: 佳雷 | G509: 佳雷-长颈鹿抱枕内衬款 | H509: CYS-JLBZCJLPWC01003 | I509: =VLOOKUP(H509,[1]物料!$A$1:$M$65536,13,0) -> 43.30 | J509: 3.5 | K509: =N509*0.05 -> 4.651 | L509: =I509+J509+K509 -> 51.451 | M509: 1 | N509: 93.02 | O509: =N509-L509 -> 41.569 | P509: =O509/N509 -> 0.44688239
A510: 260702-062096720263728 | B510: 猫人 | C510: 拼多多-猫人家具家纺旗舰店 | D510: 46205 | E510: 海马长条抱枕特大号 | F510: 眠语 | G510: 眠语-海马长条抱枕特大号 | H510: HMCTBZTDHDLS04 | I510: 52 | J510: 18 | K510: =N510*0.05 -> 7.04 | L510: =I510+J510+K510 -> 77.04 | M510: 1 | N510: 140.8 | O510: =N510-L510 -> 63.76 | P510: =O510/N510 -> 0.45284091
A511: 260702-623378481542326 | B511: 猫人 | C511: 拼多多-猫人布艺旗舰店 | D511: 46205 | E511: 锦氨男朋友枕 | F511: 永光 | G511: 永光-锦氨男朋友枕 | H511: 锦氨男朋友枕深灰色150 | I511: =VLOOKUP(H511,[1]物料!$A$1:$M$65536,13,0) -> 42.00 | J511: 8 | K511: =N511*0.05 -> 5.94 | L511: =I511+J511+K511 -> 55.94 | M511: 1 | N511: 118.8 | O511: =N511-L511 -> 62.86 | P511: =O511/N511 -> 0.52912458
A512: 260702-404540659321947 | B512: 猫人 | C512: 拼多多-猫人布艺旗舰店 | D512: 46205 | E512: 男朋友枕 | F512: 永光 | G512: 永光-男朋友枕 | H512: 男朋友枕凉感蓝 | I512: =VLOOKUP(H512,[1]物料!$A$1:$M$65536,13,0) -> 24.00 | J512: 8 | K512: =N512*0.05 -> 3.26 | L512: =I512+J512+K512 -> 35.26 | M512: 1 | N512: 65.2 | O512: =N512-L512 -> 29.94 | P512: =O512/N512 -> 0.45920245
A513: 260702-164353820223591 | B513: 初医生 | C513: 拼多多-初医生家纺官方旗舰店 | D513: 46205 | E513: 云环坐垫 | F513: 眠语 | G513: 眠语-云环坐垫 | H513: CYS-YHZDHHS | I513: =VLOOKUP(H513,[1]物料!$A$1:$M$65536,13,0) -> 20.00 | J513: 4.5 | K513: =N513*0.05 -> 2.99 | L513: =I513+J513+K513 -> 27.49 | M513: 1 | N513: 59.8 | O513: =N513-L513 -> 32.31 | P513: =O513/N513 -> 0.540301
A514: 260702-496794344960404 | B514: 猫人 | C514: 拼多多-猫人生活家具旗舰店 | D514: 46205 | E514: 圆点趴趴枕 | F514: 禹鹏 | G514: 禹鹏-圆点趴趴枕 | H514: YDPPZ-PH | I514: =VLOOKUP(H514,[1]物料!$A$1:$M$65536,13,0) -> 45.00 | J514: 6.5 | K514: =N514*0.05 -> 5.75 | L514: =I514+J514+K514 -> 57.25 | M514: 1 | N514: 115 | O514: =N514-L514 -> 57.75 | P514: =O514/N514 -> 0.50217391
A515: 5122182531993023727 | B515: 猫人 | C515: 淘宝天猫-猫人严选旗舰店 | D515: 46205 | E515: 趴趴枕套装 | F515: 禹鹏 | G515: 禹鹏-趴趴枕套装 | H515: FJL-PPZ-QH | I515: =VLOOKUP(H515,[1]物料!$A$1:$M$65536,13,0) -> 42.00 | J515: 6.5 | K515: =N515*0.05 -> 5.49 | L515: =I515+J515+K515 -> 53.99 | M515: 1 | N515: 109.8 | O515: =N515-L515 -> 55.81 | P515: =O515/N515 -> 0.5082878
A516: 260702-370000535052074 | B516: 猫人 | C516: 拼多多-猫人家具家纺旗舰店 | D516: 46205 | E516: 锦氨男朋友枕 | F516: 永光 | G516: 永光-锦氨男朋友枕 | H516: 锦氨男朋友枕蓝色 | I516: =VLOOKUP(H516,[1]物料!$A$1:$M$65536,13,0) -> 25.00 | J516: 8 | K516: =N516*0.05 -> 3.265 | L516: =I516+J516+K516 -> 36.265 | M516: 1 | N516: 65.3 | O516: =N516-L516 -> 29.035 | P516: =O516/N516 -> 0.44464012
A517: 5122184907105009642 | B517: 初医生 | C517: 淘宝天猫-初医生旗舰店 | D517: 46205 | E517: 男朋友枕 | F517: 永光 | G517: 永光-男朋友枕 | H517: 男朋友枕凉感蓝 | I517: =VLOOKUP(H517,[1]物料!$A$1:$M$65536,13,0) -> 24.00 | J517: 4.5 | K517: =N517*0.05 -> 3.3155 | L517: =I517+J517+K517 -> 31.8155 | M517: 1 | N517: 66.31 | O517: =N517-L517 -> 34.4945 | P517: =O517/N517 -> 0.52020057
A518: 3311269428860154383 | B518: 猫人 | C518: 淘宝天猫-猫人居家布艺旗舰 | D518: 46205 | E518: 8字坐垫 | F518: 佳雷 | G518: 佳雷-8字坐垫 | H518: JLZDBZPWP01003 | I518: =VLOOKUP(H518,[1]物料!$A$1:$M$65536,13,0) -> 19.90 | J518: 6.5 | K518: =N518*0.05 -> 2.99 | L518: =I518+J518+K518 -> 29.39 | M518: 1 | N518: 59.8 | O518: =N518-L518 -> 30.41 | P518: =O518/N518 -> 0.50852843
A519: 3311084281496036176 | B519: 初医生 | C519: 淘宝天猫-初医生旗舰店 | D519: 46205 | E519: 防侧睡护理枕 | F519: 佳雷 | G519: 佳雷-防侧睡护理枕 | H519: CYS-JLZTFCPWP01002 | I519: =VLOOKUP(H519,[1]物料!$A$1:$M$65536,13,0) -> 21.10 | J519: 3 | K519: =N519*0.05 -> 2.691 | L519: =I519+J519+K519 -> 26.791 | M519: 1 | N519: 53.82 | O519: =N519-L519 -> 27.029 | P519: =O519/N519 -> 0.50221107
A520: 260702-255684831541700 | B520: 猫人 | C520: 拼多多-猫人智能家居旗舰店 | D520: 46205 | E520: 防侧睡护理枕 | F520: 佳雷 | G520: 佳雷-防侧睡护理枕 | H520: JLZTFCPWP01001 | I520: =VLOOKUP(H520,[1]物料!$A$1:$M$65536,13,0) -> 21.10 | J520: 6.5 | K520: =N520*0.05 -> 2.98 | L520: =I520+J520+K520 -> 30.58 | M520: 1 | N520: 59.6 | O520: =N520-L520 -> 29.02 | P520: =O520/N520 -> 0.48691275
A521: 5122374230048032715 | B521: 初医生 | C521: 淘宝天猫-初医生旗舰店 | D521: 46205 | E521: 四叶草褥疮坐垫凝胶小菱格款 | F521: 佳雷 | G521: 佳雷-四叶草褥疮坐垫凝胶小菱格款 | H521: CYS-JLZDRCNJLGC01001 | I521: =VLOOKUP(H521,[1]物料!$A$1:$M$65536,13,0) -> 36.60 | J521: 3 | K521: =N521*0.05 -> 4.883 | L521: =I521+J521+K521 -> 44.483 | M521: 1 | N521: 97.66 | O521: =N521-L521 -> 53.177 | P521: =O521/N521 -> 0.54451157
A522: 3547462001622962 | B522: 初医生 | C522: 京东-DR.CHU 初医生官方旗舰店 | D522: 46205 | E522: 长颈鹿抱枕内衬款 | F522: 佳雷 | G522: 佳雷-长颈鹿抱枕内衬款 | H522: CYS-JLBZCJLPWC01002 | I522: =VLOOKUP(H522,[1]物料!$A$1:$M$65536,13,0) -> 43.30 | J522: 3.5 | K522: =N522*0.05 -> 5.44 | L522: =I522+J522+K522 -> 52.24 | M522: 1 | N522: 108.8 | O522: =N522-L522 -> 56.56 | P522: =O522/N522 -> 0.51985294
... A2363: 260702-063973650020635 | B2363: 猫人 | C2363: 拼多多-猫人智能家居旗舰店 | D2363: 46205 | E2363: 男朋友枕 | F2363: 永光 | G2363: 永光-男朋友枕 | H2363: 男朋友枕凉感蓝 | I2363: =VLOOKUP(H2363,[1]物料!$A$1:$M$65536,13,0) -> 24.00 | J2363: 8 | K2363: =N2363*0.05 -> 3.225 | L2363: =I2363+J2363+K2363 -> 35.225 | M2363: 1 | N2363: 64.5 | O2363: =N2363-L2363 -> 29.275 | P2363: =O2363/N2363 -> 0.45387597
A2364: 260702-224751787622168 | B2364: 猫人 | C2364: 拼多多-猫人家具家纺旗舰店 | D2364: 46205 | E2364: 海豚抱枕 | F2364: 眠语 | G2364: 眠语-海豚抱枕 | H2364: HTBZHS02 | I2364: 65 | J2364: 10.7 | K2364: =N2364*0.05 -> 8.55 | L2364: =I2364+J2364+K2364 -> 84.25 | M2364: 1 | N2364: 171 | O2364: =N2364-L2364 -> 86.75 | P2364: =O2364/N2364 -> 0.50730994
A2365: 5122058295494251444 | B2365: 初医生 | C2365: 淘宝天猫-初医生旗舰店 | D2365: 46205 | E2365: 海马长条抱枕小号 | F2365: 眠语 | G2365: 眠语-海马长条抱枕小号 | H2365: CYS-HMCTBZXHZS05 | I2365: =VLOOKUP(H2365,[1]物料!$A$1:$M$65536,13,0) -> 40.00 | J2365: 7.2 | K2365: =N2365*0.05 -> 4.6125 | L2365: =I2365+J2365+K2365 -> 51.8125 | M2365: 1 | N2365: 92.25 | O2365: =N2365-L2365 -> 40.4375 | P2365: =O2365/N2365 -> 0.43834688
A2366: 5122059555886018336 | B2366: 初医生 | C2366: 淘宝天猫-初医生旗舰店 | D2366: 46205 | E2366: 海马长条抱枕大号 | F2366: 眠语 | G2366: 眠语-海马长条抱枕大号 | H2366: CYS-HMCTBZDHHS | I2366: =VLOOKUP(H2366,[1]物料!$A$1:$M$65536,13,0) -> 40.00 | J2366: 7.2 | K2366: =N2366*0.05 -> 6.9345 | L2366: =I2366+J2366+K2366 -> 54.1345 | M2366: 1 | N2366: 138.69 | O2366: =N2366-L2366 -> 84.5555 | P2366: =O2366/N2366 -> 0.60967265
A2367: 5122566181653002525 | B2367: 初医生 | C2367: 淘宝天猫-初医生旗舰店 | D2367: 46205 | E2367: 海马长条抱枕大号 | F2367: 眠语 | G2367: 眠语-海马长条抱枕大号 | H2367: CYS-HMCTBZDHHS | I2367: =VLOOKUP(H2367,[1]物料!$A$1:$M$65536,13,0) -> 40.00 | J2367: 7.2 | K2367: =N2367*0.05 -> 6.9345 | L2367: =I2367+J2367+K2367 -> 54.1345 | M2367: 1 | N2367: 138.69 | O2367: =N2367-L2367 -> 84.5555 | P2367: =O2367/N2367 -> 0.60967265
A2368: 260702-431489042050532 | B2368: 猫人 | C2368: 拼多多-猫人布艺旗舰店 | D2368: 46205 | E2368: 拼色多功能趴睡带头枕 | F2368: 眠语 | G2368: 眠语-拼色多功能趴睡带头枕 | H2368: PSDGNPSZDTHBS10 | I2368: =VLOOKUP(H2368,[1]物料!$A$1:$M$65536,13,0) -> 48.00 | J2368: 10.7 | K2368: =N2368*0.05 -> 6.44 | L2368: =I2368+J2368+K2368 -> 65.14 | M2368: 1 | N2368: 128.8 | O2368: =N2368-L2368 -> 63.66 | P2368: =O2368/N2368 -> 0.49425466
A2369: 3310545974235018599 | B2369: 猫人 | C2369: 淘宝天猫-猫人居家布艺旗舰 | D2369: 46205 | E2369: 男朋友枕 | F2369: 永光 | G2369: 永光-男朋友枕 | H2369: 男朋友枕凉感粉 | I2369: =VLOOKUP(H2369,[1]物料!$A$1:$M$65536,13,0) -> 24.00 | J2369: 8 | K2369: =N2369*0.05 -> 3.49 | L2369: =I2369+J2369+K2369 -> 35.49 | M2369: 1 | N2369: 69.8 | O2369: =N2369-L2369 -> 34.31 | P2369: =O2369/N2369 -> 0.49154728
A2370: 3310542734899036876 | B2370: 初医生 | C2370: 淘宝天猫-初医生旗舰店 | D2370: 46205 | E2370: 响尾蛇 | F2370: 善艺 | G2370: 善艺-响尾蛇 | H2370: 响尾蛇【黑色38-39】 | I2370: =VLOOKUP(H2370,[1]物料!$A$1:$M$65536,13,0) -> 23.90 | J2370: 1.9 | K2370: =N2370*0.05 -> 2.24 | L2370: =I2370+J2370+K2370 -> 28.04 | M2370: 1 | N2370: 44.8 | O2370: =N2370-L2370 -> 16.76 | P2370: =O2370/N2370 -> 0.37410714
A2371: 260702-259690350102781 | B2371: 猫人 | C2371: 拼多多-MiiOW猫人户外用品旗舰店 | D2371: 46205 | E2371: 随行家居拖 | F2371: 佐肯 | G2371: 佐肯-随行家居拖 | H2371: 90426746663B0815 | I2371: =VLOOKUP(H2371,[1]物料!$A$1:$M$65536,13,0) -> 8.00 | J2371: 6.3 | K2371: =N2371*0.05 -> 1.05 | L2371: =I2371+J2371+K2371 -> 15.35 | M2371: 1 | N2371: 21 | O2371: =N2371-L2371 -> 5.65 | P2371: =O2371/N2371 -> 0.26904762
A2372: 260702-431489041942781 | B2372: 猫人 | C2372: 拼多多-MiiOW猫人户外用品旗舰店 | D2372: 46205 | E2372: 随行家居拖 | F2372: 佐肯 | G2372: 佐肯-随行家居拖 | H2372: 9042674666311213 | I2372: =VLOOKUP(H2372,[1]物料!$A$1:$M$65536,13,0) -> 8.00 | J2372: 6.3 | K2372: =N2372*0.05 -> 1.05 | L2372: =I2372+J2372+K2372 -> 15.35 | M2372: 1 | N2372: 21 | O2372: =N2372-L2372 -> 5.65 | P2372: =O2372/N2372 -> 0.26904762
A2373: 260702-087891658262781 | B2373: 猫人 | C2373: 拼多多-MiiOW猫人户外用品旗舰店 | D2373: 46205 | E2373: 随行家居拖 | F2373: 佐肯 | G2373: 佐肯-随行家居拖 | H2373: 9042674666371614 | I2373: =VLOOKUP(H2373,[1]物料!$A$1:$M$65536,13,0) -> 8.00 | J2373: 6.3 | K2373: =N2373*0.05 -> 1.05 | L2373: =I2373+J2373+K2373 -> 15.35 | M2373: 1 | N2373: 21 | O2373: =N2373-L2373 -> 5.65 | P2373: =O2373/N2373 -> 0.26904762
A2374: 260702-549432922512799 | B2374: 猫人 | C2374: 拼多多-猫人智能家居旗舰店 | D2374: 46205 | E2374: 男朋友枕 | F2374: 永光 | G2374: 永光-男朋友枕 | H2374: 男朋友枕凉感蓝 | I2374: =VLOOKUP(H2374,[1]物料!$A$1:$M$65536,13,0) -> 24.00 | J2374: 8 | K2374: =N2374*0.05 -> 3.435 | L2374: =I2374+J2374+K2374 -> 35.435 | M2374: 1 | N2374: 68.7 | O2374: =N2374-L2374 -> 33.265 | P2374: =O2374/N2374 -> 0.4842067
A2375: 260702-603287775661352 | B2375: 猫人 | C2375: 拼多多-猫人智能家居旗舰店 | D2375: 46205 | E2375: 男朋友枕 | F2375: 永光 | G2375: 永光-男朋友枕 | H2375: 男朋友枕凉感蓝 | I2375: =VLOOKUP(H2375,[1]物料!$A$1:$M$65536,13,0) -> 24.00 | J2375: 8 | K2375: =N2375*0.05 -> 3.435 | L2375: =I2375+J2375+K2375 -> 35.435 | M2375: 1 | N2375: 68.7 | O2375: =N2375-L2375 -> 33.265 | P2375: =O2375/N2375 -> 0.4842067
...
